<?xml version="1.0" encoding="utf-8"?>
<!-- This URDF was automatically created by SolidWorks to URDF Exporter! Originally created by Stephen Brawner (brawner@gmail.com) 
     Commit Version: 1.6.0-1-g15f4949  Build Version: 1.6.7594.29634
     For more information, please see http://wiki.ros.org/sw_urdf_exporter -->
<robot
  name="urcar_description">
  <link
    name="base_link">
    <inertial>
      <origin
        xyz="-0.293181220823497 0.0228138862846241 0.213786065129617"
        rpy="0 0 0" />
      <mass
        value="32.9716985364073" />
      <inertia
        ixx="0.747497678624552"
        ixy="-0.000136958330347952"
        ixz="-0.00109805134374165"
        iyy="0.626023554578189"
        iyz="3.13336589739395E-05"
        izz="0.227809268803597" />
    </inertial>
    <visual>
      <origin
        xyz="0 0 0"
        rpy="0 0 0" />
      <geometry>
        <mesh
          filename="package://urcar_description/meshes/base_link.STL" />
      </geometry>
      <material
        name="">
        <color
          rgba="0.741176470588235 0.901960784313726 0.956862745098039 1" />
      </material>
    </visual>
    <collision>
      <origin
        xyz="0 0 0"
        rpy="0 0 0" />
      <geometry>
        <mesh
          filename="package://urcar_description/meshes/base_link.STL" />
      </geometry>
    </collision>
  </link>
  <link
    name="right_ur_base_link">
    <inertial>
      <origin
        xyz="-1.70585556634184E-05 0.000598349980073076 0.0583820161201244"
        rpy="0 0 0" />
      <mass
        value="1.11048857887095" />
      <inertia
        ixx="0.00156521304328468"
        ixy="2.09349645709121E-07"
        ixz="-1.23145085442165E-06"
        iyy="0.00158402822015484"
        iyz="1.40529519995404E-05"
        izz="0.0017882187974853" />
    </inertial>
    <visual>
      <origin
        xyz="0 0 0"
        rpy="0 0 0" />
      <geometry>
        <mesh
          filename="package://urcar_description/meshes/right_ur_base_link.STL" />
      </geometry>
      <material
        name="">
        <color
          rgba="0.898039215686275 0.917647058823529 0.929411764705882 1" />
      </material>
    </visual>
    <collision>
      <origin
        xyz="0 0 0"
        rpy="0 0 0" />
      <geometry>
        <mesh
          filename="package://urcar_description/meshes/right_ur_base_link.STL" />
      </geometry>
    </collision>
  </link>
  <joint
    name="right_ur_base"
    type="fixed">
    <origin
      xyz="-0.0900695574684298 -0.0295000000000024 0.127505494505501"
      rpy="-1.5707963267949 0 3.14159265358979" />
    <parent
      link="base_link" />
    <child
      link="right_ur_base_link" />
    <axis
      xyz="0 0 0" />
  </joint>
  <link
    name="right_ur_shoulder_link">
    <inertial>
      <origin
        xyz="-2.75438503311021E-07 -0.0095503335634608 -0.00134313880089604"
        rpy="0 0 0" />
      <mass
        value="0.86048677353649" />
      <inertia
        ixx="0.00145975698843663"
        ixy="1.00076031707848E-08"
        ixz="1.13510071513689E-08"
        iyy="0.00124606811007042"
        iyz="3.34902185535162E-05"
        izz="0.0011307880280091" />
    </inertial>
    <visual>
      <origin
        xyz="0 0 0"
        rpy="0 0 0" />
      <geometry>
        <mesh
          filename="package://urcar_description/meshes/right_ur_shoulder_link.STL" />
      </geometry>
      <material
        name="">
        <color
          rgba="1 1 1 1" />
      </material>
    </visual>
    <collision>
      <origin
        xyz="0 0 0"
        rpy="0 0 0" />
      <geometry>
        <mesh
          filename="package://urcar_description/meshes/right_ur_shoulder_link.STL" />
      </geometry>
    </collision>
  </link>
  <joint
    name="right_ur_shoulder_pan_joint"
    type="revolute">
    <origin
      xyz="0 0 0.15185"
      rpy="0 0 0" />
    <parent
      link="right_ur_base_link" />
    <child
      link="right_ur_shoulder_link" />
    <axis
      xyz="0 0 1" />
    <limit
      lower="-3.14"
      upper="3.14"
      effort="0"
      velocity="0" />
  </joint>
  <link
    name="right_ur_upper_arm_link">
    <inertial>
      <origin
        xyz="-0.103646398649669 1.59543779154614E-06 0.120186719515414"
        rpy="0 0 0" />
      <mass
        value="1.86255115311105" />
      <inertia
        ixx="0.00213324581133399"
        ixy="8.33210613154706E-07"
        ixz="0.00038601878673668"
        iyy="0.0202440252631196"
        iyz="-1.82478927308902E-07"
        izz="0.0196974069542396" />
    </inertial>
    <visual>
      <origin
        xyz="0 0 0"
        rpy="0 0 0" />
      <geometry>
        <mesh
          filename="package://urcar_description/meshes/right_ur_upper_arm_link.STL" />
      </geometry>
      <material
        name="">
        <color
          rgba="1 1 1 1" />
      </material>
    </visual>
    <collision>
      <origin
        xyz="0 0 0"
        rpy="0 0 0" />
      <geometry>
        <mesh
          filename="package://urcar_description/meshes/right_ur_upper_arm_link.STL" />
      </geometry>
    </collision>
  </link>
  <joint
    name="right_ur_shoulder_lift_joint"
    type="revolute">
    <origin
      xyz="0 0 0"
      rpy="1.5708 0 0" />
    <parent
      link="right_ur_shoulder_link" />
    <child
      link="right_ur_upper_arm_link" />
    <axis
      xyz="0 0 1" />
    <limit
      lower="-3.14"
      upper="3.14"
      effort="0"
      velocity="0" />
  </joint>
  <link
    name="right_ur_forearm_link">
    <inertial>
      <origin
        xyz="-0.113365957442825 3.44573695298944E-07 0.00470876633326606"
        rpy="0 0 0" />
      <mass
        value="0.888801909346324" />
      <inertia
        ixx="0.000601695226725028"
        ixy="2.34953077021263E-08"
        ixz="-0.00047433984876308"
        iyy="0.00677879949972356"
        iyz="2.32200841032818E-09"
        izz="0.00662395723523755" />
    </inertial>
    <visual>
      <origin
        xyz="0 0 0"
        rpy="0 0 0" />
      <geometry>
        <mesh
          filename="package://urcar_description/meshes/right_ur_forearm_link.STL" />
      </geometry>
      <material
        name="">
        <color
          rgba="1 1 1 1" />
      </material>
    </visual>
    <collision>
      <origin
        xyz="0 0 0"
        rpy="0 0 0" />
      <geometry>
        <mesh
          filename="package://urcar_description/meshes/right_ur_forearm_link.STL" />
      </geometry>
    </collision>
  </link>
  <joint
    name="right_ur_elbow_joint"
    type="revolute">
    <origin
      xyz="-0.24355 0 0.027"
      rpy="0 0 0" />
    <parent
      link="right_ur_upper_arm_link" />
    <child
      link="right_ur_forearm_link" />
    <axis
      xyz="0 0 1" />
    <limit
      lower="-3.14"
      upper="3.14"
      effort="0"
      velocity="0" />
  </joint>
  <link
    name="right_ur_wrist_1_link">
    <inertial>
      <origin
        xyz="1.51425311289977E-07 -3.97067190331946E-05 -0.0124956497436929"
        rpy="0 0 0" />
      <mass
        value="0.375036968075586" />
      <inertia
        ixx="0.000411752859619136"
        ixy="1.48665201195272E-09"
        ixz="-5.48241411917674E-09"
        iyy="0.000316313144134685"
        iyz="2.384364866386E-06"
        izz="0.000288187892179436" />
    </inertial>
    <visual>
      <origin
        xyz="0 0 0"
        rpy="0 0 0" />
      <geometry>
        <mesh
          filename="package://urcar_description/meshes/right_ur_wrist_1_link.STL" />
      </geometry>
      <material
        name="">
        <color
          rgba="1 1 1 1" />
      </material>
    </visual>
    <collision>
      <origin
        xyz="0 0 0"
        rpy="0 0 0" />
      <geometry>
        <mesh
          filename="package://urcar_description/meshes/right_ur_wrist_1_link.STL" />
      </geometry>
    </collision>
  </link>
  <joint
    name="right_ur_wrist_1_joint"
    type="revolute">
    <origin
      xyz="-0.2132 0 0.10405"
      rpy="0 0 0" />
    <parent
      link="right_ur_forearm_link" />
    <child
      link="right_ur_wrist_1_link" />
    <axis
      xyz="0 0 1" />
    <limit
      lower="-3.14"
      upper="3.14"
      effort="0"
      velocity="0" />
  </joint>
  <link
    name="right_ur_wrist_2_link">
    <inertial>
      <origin
        xyz="4.59401394703463E-08 3.09304237351427E-05 -0.00528976846149043"
        rpy="0 0 0" />
      <mass
        value="0.316863918999266" />
      <inertia
        ixx="0.000290365349607398"
        ixy="6.89739045564851E-11"
        ixz="5.13087527877654E-09"
        iyy="0.000194794626867655"
        iyz="-2.33431027426877E-06"
        izz="0.000259464598147467" />
    </inertial>
    <visual>
      <origin
        xyz="0 0 0"
        rpy="0 0 0" />
      <geometry>
        <mesh
          filename="package://urcar_description/meshes/right_ur_wrist_2_link.STL" />
      </geometry>
      <material
        name="">
        <color
          rgba="1 1 1 1" />
      </material>
    </visual>
    <collision>
      <origin
        xyz="0 0 0"
        rpy="0 0 0" />
      <geometry>
        <mesh
          filename="package://urcar_description/meshes/right_ur_wrist_2_link.STL" />
      </geometry>
    </collision>
  </link>
  <joint
    name="right_ur_wrist_2_joint"
    type="revolute">
    <origin
      xyz="0 -0.08535 0"
      rpy="1.5708 0 0" />
    <parent
      link="right_ur_wrist_1_link" />
    <child
      link="right_ur_wrist_2_link" />
    <axis
      xyz="0 0 1" />
    <limit
      lower="-3.14"
      upper="3.14"
      effort="0"
      velocity="0" />
  </joint>
  <link
    name="right_ur_wrist_3_link">
    <inertial>
      <origin
        xyz="-2.16463893476515E-08 0.000153725135783267 -0.0253521485792833"
        rpy="0 0 0" />
      <mass
        value="0.145961783256663" />
      <inertia
        ixx="6.30289584549884E-05"
        ixy="-2.27263392701082E-10"
        ixz="-1.04791051790363E-10"
        iyy="6.35887495748845E-05"
        iyz="-3.62022482896663E-08"
        izz="7.28000634102573E-05" />
    </inertial>
    <visual>
      <origin
        xyz="0 0 0"
        rpy="0 0 0" />
      <geometry>
        <mesh
          filename="package://urcar_description/meshes/right_ur_wrist_3_link.STL" />
      </geometry>
      <material
        name="">
        <color
          rgba="1 1 1 1" />
      </material>
    </visual>
    <collision>
      <origin
        xyz="0 0 0"
        rpy="0 0 0" />
      <geometry>
        <mesh
          filename="package://urcar_description/meshes/right_ur_wrist_3_link.STL" />
      </geometry>
    </collision>
  </link>
  <joint
    name="right_ur_wrist_3_joint"
    type="revolute">
    <origin
      xyz="0 0.0921 0"
      rpy="-1.5708 0 0" />
    <parent
      link="right_ur_wrist_2_link" />
    <child
      link="right_ur_wrist_3_link" />
    <axis
      xyz="0 0 1" />
    <limit
      lower="-3.14"
      upper="3.14"
      effort="0"
      velocity="0" />
  </joint>
  <link
    name="left_ur_base_link">
    <inertial>
      <origin
        xyz="-1.70585560592962E-05 0.000598349978268964 0.0583820161197486"
        rpy="0 0 0" />
      <mass
        value="1.11048857899584" />
      <inertia
        ixx="0.00156521304331817"
        ixy="2.09349636447583E-07"
        ixz="-1.23145085784408E-06"
        iyy="0.00158402822015454"
        iyz="1.40529519917085E-05"
        izz="0.00178821879751267" />
    </inertial>
    <visual>
      <origin
        xyz="0 0 0"
        rpy="0 0 0" />
      <geometry>
        <mesh
          filename="package://urcar_description/meshes/left_ur_base_link.STL" />
      </geometry>
      <material
        name="">
        <color
          rgba="0.898039215686275 0.917647058823529 0.929411764705882 1" />
      </material>
    </visual>
    <collision>
      <origin
        xyz="0 0 0"
        rpy="0 0 0" />
      <geometry>
        <mesh
          filename="package://urcar_description/meshes/left_ur_base_link.STL" />
      </geometry>
    </collision>
  </link>
  <joint
    name="left_ur_base"
    type="fixed">
    <origin
      xyz="-0.09007 0.0305 0.12751"
      rpy="-1.5708 0 0" />
    <parent
      link="base_link" />
    <child
      link="left_ur_base_link" />
    <axis
      xyz="0 0 0" />
  </joint>
  <link
    name="left_ur_shoulder_link">
    <inertial>
      <origin
        xyz="-9.67599977086397E-08 -0.00955031302882908 -0.00134307624352892"
        rpy="0 0 0" />
      <mass
        value="0.860481773538634" />
      <inertia
        ixx="0.00145975703636161"
        ixy="1.00342656563931E-08"
        ixz="1.13363669644073E-08"
        iyy="0.00124606797307752"
        iyz="3.34902394955827E-05"
        izz="0.00113078792734696" />
    </inertial>
    <visual>
      <origin
        xyz="0 0 0"
        rpy="0 0 0" />
      <geometry>
        <mesh
          filename="package://urcar_description/meshes/left_ur_shoulder_link.STL" />
      </geometry>
      <material
        name="">
        <color
          rgba="1 1 1 1" />
      </material>
    </visual>
    <collision>
      <origin
        xyz="0 0 0"
        rpy="0 0 0" />
      <geometry>
        <mesh
          filename="package://urcar_description/meshes/left_ur_shoulder_link.STL" />
      </geometry>
    </collision>
  </link>
  <joint
    name="left_ur_shoulder_pan_joint"
    type="revolute">
    <origin
      xyz="0 0 0.15185"
      rpy="0 0 0" />
    <parent
      link="left_ur_base_link" />
    <child
      link="left_ur_shoulder_link" />
    <axis
      xyz="0 0 1" />
    <limit
      lower="-3.14"
      upper="3.14"
      effort="0"
      velocity="0" />
  </joint>
  <link
    name="left_ur_upper_arm_link">
    <inertial>
      <origin
        xyz="-0.103646361909403 1.57794692867697E-06 0.120186715762299"
        rpy="0 0 0" />
      <mass
        value="1.86255217904093" />
      <inertia
        ixx="0.00213324549329523"
        ixy="8.3296461192486E-07"
        ixz="0.000386018430757662"
        iyy="0.0202440239369208"
        iyz="-1.82464647232383E-07"
        izz="0.019697405360556" />
    </inertial>
    <visual>
      <origin
        xyz="0 0 0"
        rpy="0 0 0" />
      <geometry>
        <mesh
          filename="package://urcar_description/meshes/left_ur_upper_arm_link.STL" />
      </geometry>
      <material
        name="">
        <color
          rgba="1 1 1 1" />
      </material>
    </visual>
    <collision>
      <origin
        xyz="0 0 0"
        rpy="0 0 0" />
      <geometry>
        <mesh
          filename="package://urcar_description/meshes/left_ur_upper_arm_link.STL" />
      </geometry>
    </collision>
  </link>
  <joint
    name="left_ur_shoulder_lift_joint"
    type="revolute">
    <origin
      xyz="0 0 0"
      rpy="1.5708 0 0" />
    <parent
      link="left_ur_shoulder_link" />
    <child
      link="left_ur_upper_arm_link" />
    <axis
      xyz="0 0 1" />
    <limit
      lower="-3.14"
      upper="3.14"
      effort="0"
      velocity="0" />
  </joint>
  <link
    name="left_ur_forearm_link">
    <inertial>
      <origin
        xyz="-0.113365959382854 3.44232148341561E-07 0.0047087655741031"
        rpy="0 0 0" />
      <mass
        value="0.888801942898712" />
      <inertia
        ixx="0.000601695179250581"
        ixy="2.34046232809796E-08"
        ixz="-0.00047433985025688"
        iyy="0.00677879951041521"
        iyz="2.29736419364682E-09"
        izz="0.0066239572943536" />
    </inertial>
    <visual>
      <origin
        xyz="0 0 0"
        rpy="0 0 0" />
      <geometry>
        <mesh
          filename="package://urcar_description/meshes/left_ur_forearm_link.STL" />
      </geometry>
      <material
        name="">
        <color
          rgba="1 1 1 1" />
      </material>
    </visual>
    <collision>
      <origin
        xyz="0 0 0"
        rpy="0 0 0" />
      <geometry>
        <mesh
          filename="package://urcar_description/meshes/left_ur_forearm_link.STL" />
      </geometry>
    </collision>
  </link>
  <joint
    name="left_ur_elbow_joint"
    type="revolute">
    <origin
      xyz="-0.24355 0 0.027"
      rpy="0 0 0" />
    <parent
      link="left_ur_upper_arm_link" />
    <child
      link="left_ur_forearm_link" />
    <axis
      xyz="0 0 1" />
    <limit
      lower="-3.14"
      upper="3.14"
      effort="0"
      velocity="0" />
  </joint>
  <link
    name="left_ur_wrist_1_link">
    <inertial>
      <origin
        xyz="1.51219308242023E-07 -3.97060497587809E-05 -0.012495648667315"
        rpy="0 0 0" />
      <mass
        value="0.375036952925017" />
      <inertia
        ixx="0.000411752842139784"
        ixy="1.48469142584213E-09"
        ixz="-5.48361636303738E-09"
        iyy="0.000316313128446611"
        iyz="2.38437183463293E-06"
        izz="0.000288187883829113" />
    </inertial>
    <visual>
      <origin
        xyz="0 0 0"
        rpy="0 0 0" />
      <geometry>
        <mesh
          filename="package://urcar_description/meshes/left_ur_wrist_1_link.STL" />
      </geometry>
      <material
        name="">
        <color
          rgba="1 1 1 1" />
      </material>
    </visual>
    <collision>
      <origin
        xyz="0 0 0"
        rpy="0 0 0" />
      <geometry>
        <mesh
          filename="package://urcar_description/meshes/left_ur_wrist_1_link.STL" />
      </geometry>
    </collision>
  </link>
  <joint
    name="left_ur_wrist_1_joint"
    type="revolute">
    <origin
      xyz="-0.2132 0 0.10405"
      rpy="0 0 0" />
    <parent
      link="left_ur_forearm_link" />
    <child
      link="left_ur_wrist_1_link" />
    <axis
      xyz="0 0 1" />
    <limit
      lower="-3.14"
      upper="3.14"
      effort="0"
      velocity="0" />
  </joint>
  <link
    name="left_ur_wrist_2_link">
    <inertial>
      <origin
        xyz="6.10124055167027E-08 3.09384468485385E-05 -0.0052897738204587"
        rpy="0 0 0" />
      <mass
        value="0.316864132517896" />
      <inertia
        ixx="0.000290365363147334"
        ixy="1.42976604993195E-10"
        ixz="5.17000987218734E-09"
        iyy="0.00019479476406711"
        iyz="-2.33427646368357E-06"
        izz="0.000259464723052012" />
    </inertial>
    <visual>
      <origin
        xyz="0 0 0"
        rpy="0 0 0" />
      <geometry>
        <mesh
          filename="package://urcar_description/meshes/left_ur_wrist_2_link.STL" />
      </geometry>
      <material
        name="">
        <color
          rgba="1 1 1 1" />
      </material>
    </visual>
    <collision>
      <origin
        xyz="0 0 0"
        rpy="0 0 0" />
      <geometry>
        <mesh
          filename="package://urcar_description/meshes/left_ur_wrist_2_link.STL" />
      </geometry>
    </collision>
  </link>
  <joint
    name="left_ur_wrist_2_joint"
    type="revolute">
    <origin
      xyz="0 -0.08535 0"
      rpy="1.5708 0 0" />
    <parent
      link="left_ur_wrist_1_link" />
    <child
      link="left_ur_wrist_2_link" />
    <axis
      xyz="0 0 1" />
    <limit
      lower="-3.14"
      upper="3.14"
      effort="0"
      velocity="0" />
  </joint>
  <link
    name="left_ur_wrist_3_link">
    <inertial>
      <origin
        xyz="-2.16463894031627E-08 0.000153725135783267 -0.0253521485792833"
        rpy="0 0 0" />
      <mass
        value="0.145961783256662" />
      <inertia
        ixx="6.30289584549874E-05"
        ixy="-2.27263392707742E-10"
        ixz="-1.04791051677919E-10"
        iyy="6.35887495748838E-05"
        iyz="-3.62022482900433E-08"
        izz="7.28000634102562E-05" />
    </inertial>
    <visual>
      <origin
        xyz="0 0 0"
        rpy="0 0 0" />
      <geometry>
        <mesh
          filename="package://urcar_description/meshes/left_ur_wrist_3_link.STL" />
      </geometry>
      <material
        name="">
        <color
          rgba="1 1 1 1" />
      </material>
    </visual>
    <collision>
      <origin
        xyz="0 0 0"
        rpy="0 0 0" />
      <geometry>
        <mesh
          filename="package://urcar_description/meshes/left_ur_wrist_3_link.STL" />
      </geometry>
    </collision>
  </link>
  <joint
    name="left_ur_wrist_3_joint"
    type="revolute">
    <origin
      xyz="0 0.0921 0"
      rpy="-1.5708 0 0" />
    <parent
      link="left_ur_wrist_2_link" />
    <child
      link="left_ur_wrist_3_link" />
    <axis
      xyz="0 0 1" />
    <limit
      lower="-3.14"
      upper="3.14"
      effort="0"
      velocity="0" />
  </joint>
</robot>
